2022-08-30 10:38:36,861 : INFO : root : Loading config.
2022-08-30 10:38:36,867 : INFO : YamlMultifileConfigLoader : Machine config file #1: config.yaml
2022-08-30 10:38:36,867 : INFO : ConfigProcessor : Loading config from cache: /tmp/5251055949d167756f63ede37e444bb8.mpf_cache
2022-08-30 10:38:36,932 : INFO : ConfigProcessor : Loading config from cache: /tmp/f9e3dd4704f85a1981134d11860e8190.mpf_cache
2022-08-30 10:38:36,933 : INFO : ConfigProcessor : Loading config from cache: /tmp/973d4e7a920ce70e84cdae92155661d2.mpf_cache
2022-08-30 10:38:36,934 : INFO : ConfigProcessor : Loading config from cache: /tmp/c263835eea05018f0e1b2484a463cfd0.mpf_cache
2022-08-30 10:38:36,935 : INFO : ConfigProcessor : Loading config from cache: /tmp/b44a335d40507c0f628b4f10d8bdbe3d.mpf_cache
2022-08-30 10:38:36,935 : INFO : ConfigProcessor : Loading config from cache: /tmp/0ddf414cfccb2c0452c35cfa8a9dd932.mpf_cache
2022-08-30 10:38:36,936 : INFO : ConfigProcessor : Loading config from cache: /tmp/3c5ed8820afd558a1694414def6eff9e.mpf_cache
2022-08-30 10:38:36,937 : INFO : ConfigProcessor : Loading config from cache: /tmp/d2988ecd206705de1912aa00bbd6a8b6.mpf_cache
2022-08-30 10:38:36,937 : INFO : ConfigProcessor : Loading config from cache: /tmp/28df6b6086bac6bd1736f21d72b88a0b.mpf_cache
2022-08-30 10:38:36,938 : INFO : ConfigProcessor : Loading config from file /home/ohm/projects/embedded/55-pinball/mpf-beerfest/modes/multiball/config/multiball.yaml.
2022-08-30 10:38:36,953 : INFO : ConfigProcessor : Loading config: /home/ohm/projects/embedded/55-pinball/mpf-beerfest/modes/multiball/config/multiball.yaml
2022-08-30 10:38:36,953 : INFO : ConfigProcessor : Config file cache created: /tmp/9468e964d578542decf2e18e21bf4852.mpf_cache
2022-08-30 10:38:36,954 : INFO : ConfigProcessor : Loading config from cache: /tmp/e5f9b86e5f4b96e36fc897d512b252a6.mpf_cache
2022-08-30 10:38:36,955 : INFO : ConfigProcessor : Loading config from cache: /tmp/15e84690bd995590cd3b1c0b3545ce43.mpf_cache
2022-08-30 10:38:36,956 : INFO : ConfigProcessor : Loading config from cache: /tmp/225a5d974283937307bc0e739d5c1a8f.mpf_cache
2022-08-30 10:38:36,956 : INFO : ConfigProcessor : Loading config from cache: /tmp/4635650b31546e1baa7aee010f8c2c4d.mpf_cache
2022-08-30 10:38:36,956 : INFO : ConfigProcessor : Loading config from cache: /tmp/cb9177e792f641e361fc7dac01137a90.mpf_cache
2022-08-30 10:38:36,957 : INFO : ConfigProcessor : Loading config from cache: /tmp/a24b2382fbd67cc142a9a6f3663d7122.mpf_cache
2022-08-30 10:38:36,957 : INFO : ConfigProcessor : Loading config from cache: /tmp/e7e96e5c75caa9bd3cb8b231ecbc6017.mpf_cache
2022-08-30 10:38:36,958 : INFO : ConfigProcessor : Loading config from cache: /tmp/eef157c123e6f8b805af551151f02a60.mpf_cache
2022-08-30 10:38:36,958 : INFO : ConfigProcessor : Loading config from cache: /tmp/c3d5cb164dea000742e09e9079929b1c.mpf_cache
2022-08-30 10:38:36,959 : INFO : ConfigProcessor : Loading config from cache: /tmp/474c711d458d32a388c385883d78b8e5.mpf_cache
2022-08-30 10:38:36,959 : INFO : ConfigProcessor : Loading config from cache: /tmp/6e4ae55d94b4111c75c2be55a051e25f.mpf_cache
2022-08-30 10:38:36,959 : INFO : ConfigProcessor : Loading config from cache: /tmp/6ea31842a955eda2b517dcfd824ead3e.mpf_cache
2022-08-30 10:38:36,961 : INFO : ConfigProcessor : Loading config from cache: /tmp/bd17fdc7cc405fa6d585e392ecb7d869.mpf_cache
2022-08-30 10:38:36,961 : INFO : ConfigProcessor : Loading config from cache: /tmp/3ddda0b724fcfbf58214cd2d964fd28b.mpf_cache
2022-08-30 10:38:36,962 : INFO : ConfigProcessor : Loading config from cache: /tmp/4c8982e8fec21961dcac5e3624b63382.mpf_cache
2022-08-30 10:38:36,962 : INFO : ConfigProcessor : Loading config from cache: /tmp/e3cc8890e0f3cdbfb9a0aaf9e93a7560.mpf_cache
2022-08-30 10:38:36,964 : INFO : Machine : Mission Pinball Framework Core Engine v0.55.0
2022-08-30 10:38:36,964 : INFO : Machine : Command line arguments: {'no_load_cache': False, 'create_config_cache': True, 'bcp': True, 'configfile': ['config.yaml'], 'force_assets_load': False, 'jsonlogging': False, 'logfile': 'logs/2022-08-30-10-38-36-mpf-dev-lappy.log', 'pause': False, 'production': False, 'text_ui': False, 'loglevel': 15, 'consoleloglevel': 10, 'force_platform': 'virtual', 'syslog_address': None, 'mc_file_name': None, 'no_sound': False}
2022-08-30 10:38:36,964 : INFO : Machine : MPF path: /usr/local/lib/python3.8/dist-packages/mpf
2022-08-30 10:38:36,965 : INFO : Machine : Machine path: /home/ohm/projects/embedded/55-pinball/mpf-beerfest
2022-08-30 10:38:36,965 : INFO : Machine : Platform: linux
2022-08-30 10:38:36,965 : INFO : Machine : Python executable location: /usr/bin/python3
2022-08-30 10:38:36,965 : INFO : Machine : Python version: 3.8.10 (64-bit)
2022-08-30 10:38:36,967 : INFO : Machine : Initialise MPF.
2022-08-30 10:38:37,007 : INFO : EventManager : Event: ======'machine_var_credits_string'====== Args={'value': 'FREE PLAY', 'prev_value': None, 'change': True}
2022-08-30 10:38:37,046 : INFO : EventManager : Event: ======'machine_var_master_volume'====== Args={'value': 0.5, 'prev_value': None, 'change': True}
2022-08-30 10:38:37,046 : INFO : EventManager : Event: ======'machine_var_player1_score'====== Args={'value': 180400, 'prev_value': None, 'change': True}
2022-08-30 10:38:37,046 : INFO : EventManager : Event: ======'machine_var_mpf_version'====== Args={'value': 'MPF v0.55.0', 'prev_value': None, 'change': True}
2022-08-30 10:38:37,046 : INFO : EventManager : Event: ======'machine_var_mpf_extended_version'====== Args={'value': 'MPF v0.55.0, Config version:5, Show version: 5, BCP version:1.1', 'prev_value': None, 'change': True}
2022-08-30 10:38:37,047 : INFO : EventManager : Event: ======'machine_var_python_version'====== Args={'value': '3.8.10', 'prev_value': None, 'change': True}
2022-08-30 10:38:37,063 : INFO : EventManager : Event: ======'machine_var_platform'====== Args={'value': 'Linux-5.15.0-46-generic-x86_64-with-glibc2.29', 'prev_value': None, 'change': True}
2022-08-30 10:38:37,063 : INFO : EventManager : Event: ======'machine_var_platform_system'====== Args={'value': 'Linux', 'prev_value': None, 'change': True}
2022-08-30 10:38:37,063 : INFO : EventManager : Event: ======'machine_var_platform_release'====== Args={'value': '5.15.0-46-generic', 'prev_value': None, 'change': True}
2022-08-30 10:38:37,063 : INFO : EventManager : Event: ======'machine_var_platform_version'====== Args={'value': '#49~20.04.1-Ubuntu SMP Thu Aug 4 19:15:44 UTC 2022', 'prev_value': None, 'change': True}
2022-08-30 10:38:37,063 : INFO : EventManager : Event: ======'machine_var_platform_machine'====== Args={'value': 'x86_64', 'prev_value': None, 'change': True}
2022-08-30 10:38:37,063 : INFO : EventManager : Event: ======'init_phase_1'====== Args={}
2022-08-30 10:38:37,099 : ERROR : asyncio : Exception in callback EventManager._async_handler_done(<QueuedEvent>)(<Task finishe...our config.')>) at /usr/local/lib/python3.8/dist-packages/mpf/core/events.py:112
handle: <Handle EventManager._async_handler_done(<QueuedEvent>)(<Task finishe...our config.')>) at /usr/local/lib/python3.8/dist-packages/mpf/core/events.py:112>
Traceback (most recent call last):
  File "/usr/lib/python3.8/asyncio/events.py", line 81, in _run
    self._context.run(self._callback, *self._args)
  File "/usr/local/lib/python3.8/dist-packages/mpf/core/events.py", line 115, in _async_handler_done
    future.result()
  File "/usr/local/lib/python3.8/dist-packages/mpf/core/device_manager.py", line 90, in _load_device_modules
    await self.machine.mode_controller.load_mode_devices()
  File "/usr/local/lib/python3.8/dist-packages/mpf/core/mode_controller.py", line 86, in load_mode_devices
    await mode.load_mode_devices()
  File "/usr/local/lib/python3.8/dist-packages/mpf/core/mode.py", line 431, in load_mode_devices
    settings = device.validate_and_parse_config(settings, True, "mode:" + self.name)
  File "/usr/local/lib/python3.8/dist-packages/mpf/core/device.py", line 108, in validate_and_parse_config
    self.machine.config_validator.validate_config(
  File "/usr/local/lib/python3.8/dist-packages/mpf/core/config_validator.py", line 179, in validate_config
    return self._validate_config(config_spec, source, base_spec=base_spec, add_missing_keys=add_missing_keys,
  File "/usr/local/lib/python3.8/dist-packages/mpf/core/config_validator.py", line 220, in _validate_config
    processed_config[k] = self.validate_config_item(
  File "/usr/local/lib/python3.8/dist-packages/mpf/core/config_validator.py", line 272, in validate_config_item
    new_list.append(self.validate_item(i, validation, validation_failure_info))
  File "/usr/local/lib/python3.8/dist-packages/mpf/core/config_validator.py", line 709, in validate_item
    return self.validator_list[validator](item, validation_failure_info=validation_failure_info, param=param)
  File "/usr/local/lib/python3.8/dist-packages/mpf/core/config_validator.py", line 422, in _validate_type_machine
    return self.validation_error(item, validation_failure_info,
  File "/usr/local/lib/python3.8/dist-packages/mpf/core/config_validator.py", line 726, in validation_error
    raise ConfigFileError("Config validation error: Entry {} = \"{}\" is not valid. {}".format(
mpf.exceptions.config_file_error.ConfigFileError: Config File Error in ConfigValidator: Config validation error: Entry mode:multiball:multiball_locks:pt_lock:lock_devices = "XXX" is not valid. Device "XXX" not found in "ball_devices:" section in your config. Error Code: CFE-ConfigValidator-6 (https://docs.missionpinball.org/en/0.55/logs/CFE-ConfigValidator-6.html)
2022-08-30 10:38:37,105 : INFO : Machine : Starting the main run loop.
2022-08-30 10:38:37,105 : INFO : Machine : Shutting down...
2022-08-30 10:38:37,105 : INFO : EventManager : Event: ======'shutdown'====== Args={}
2022-08-30 10:38:37,106 : ERROR : Machine : Runtime Exception
Traceback (most recent call last):
  File "/usr/local/lib/python3.8/dist-packages/mpf/core/machine.py", line 769, in _run_loop
    raise self._exception['exception']
  File "/usr/lib/python3.8/asyncio/events.py", line 81, in _run
    self._context.run(self._callback, *self._args)
  File "/usr/local/lib/python3.8/dist-packages/mpf/core/events.py", line 115, in _async_handler_done
    future.result()
  File "/usr/local/lib/python3.8/dist-packages/mpf/core/device_manager.py", line 90, in _load_device_modules
    await self.machine.mode_controller.load_mode_devices()
  File "/usr/local/lib/python3.8/dist-packages/mpf/core/mode_controller.py", line 86, in load_mode_devices
    await mode.load_mode_devices()
  File "/usr/local/lib/python3.8/dist-packages/mpf/core/mode.py", line 431, in load_mode_devices
    settings = device.validate_and_parse_config(settings, True, "mode:" + self.name)
  File "/usr/local/lib/python3.8/dist-packages/mpf/core/device.py", line 108, in validate_and_parse_config
    self.machine.config_validator.validate_config(
  File "/usr/local/lib/python3.8/dist-packages/mpf/core/config_validator.py", line 179, in validate_config
    return self._validate_config(config_spec, source, base_spec=base_spec, add_missing_keys=add_missing_keys,
  File "/usr/local/lib/python3.8/dist-packages/mpf/core/config_validator.py", line 220, in _validate_config
    processed_config[k] = self.validate_config_item(
  File "/usr/local/lib/python3.8/dist-packages/mpf/core/config_validator.py", line 272, in validate_config_item
    new_list.append(self.validate_item(i, validation, validation_failure_info))
  File "/usr/local/lib/python3.8/dist-packages/mpf/core/config_validator.py", line 709, in validate_item
    return self.validator_list[validator](item, validation_failure_info=validation_failure_info, param=param)
  File "/usr/local/lib/python3.8/dist-packages/mpf/core/config_validator.py", line 422, in _validate_type_machine
    return self.validation_error(item, validation_failure_info,
  File "/usr/local/lib/python3.8/dist-packages/mpf/core/config_validator.py", line 726, in validation_error
    raise ConfigFileError("Config validation error: Entry {} = \"{}\" is not valid. {}".format(
mpf.exceptions.config_file_error.ConfigFileError: Config File Error in ConfigValidator: Config validation error: Entry mode:multiball:multiball_locks:pt_lock:lock_devices = "XXX" is not valid. Device "XXX" not found in "ball_devices:" section in your config. Error Code: CFE-ConfigValidator-6 (https://docs.missionpinball.org/en/0.55/logs/CFE-ConfigValidator-6.html)
2022-09-09 13:30:35,268 : ERROR : root : Received second SIGINT. Will exit ungracefully!
Traceback (most recent call last):
  File "/usr/local/lib/python3.8/dist-packages/mpf/core/machine.py", line 769, in _run_loop
    raise self._exception['exception']
  File "/usr/lib/python3.8/asyncio/events.py", line 81, in _run
    self._context.run(self._callback, *self._args)
  File "/usr/local/lib/python3.8/dist-packages/mpf/core/events.py", line 115, in _async_handler_done
    future.result()
  File "/usr/local/lib/python3.8/dist-packages/mpf/core/device_manager.py", line 90, in _load_device_modules
    await self.machine.mode_controller.load_mode_devices()
  File "/usr/local/lib/python3.8/dist-packages/mpf/core/mode_controller.py", line 86, in load_mode_devices
    await mode.load_mode_devices()
  File "/usr/local/lib/python3.8/dist-packages/mpf/core/mode.py", line 431, in load_mode_devices
    settings = device.validate_and_parse_config(settings, True, "mode:" + self.name)
  File "/usr/local/lib/python3.8/dist-packages/mpf/core/device.py", line 108, in validate_and_parse_config
    self.machine.config_validator.validate_config(
  File "/usr/local/lib/python3.8/dist-packages/mpf/core/config_validator.py", line 179, in validate_config
    return self._validate_config(config_spec, source, base_spec=base_spec, add_missing_keys=add_missing_keys,
  File "/usr/local/lib/python3.8/dist-packages/mpf/core/config_validator.py", line 220, in _validate_config
    processed_config[k] = self.validate_config_item(
  File "/usr/local/lib/python3.8/dist-packages/mpf/core/config_validator.py", line 272, in validate_config_item
    new_list.append(self.validate_item(i, validation, validation_failure_info))
  File "/usr/local/lib/python3.8/dist-packages/mpf/core/config_validator.py", line 709, in validate_item
    return self.validator_list[validator](item, validation_failure_info=validation_failure_info, param=param)
  File "/usr/local/lib/python3.8/dist-packages/mpf/core/config_validator.py", line 422, in _validate_type_machine
    return self.validation_error(item, validation_failure_info,
  File "/usr/local/lib/python3.8/dist-packages/mpf/core/config_validator.py", line 726, in validation_error
    raise ConfigFileError("Config validation error: Entry {} = \"{}\" is not valid. {}".format(
mpf.exceptions.config_file_error.ConfigFileError: Config File Error in ConfigValidator: Config validation error: Entry mode:multiball:multiball_locks:pt_lock:lock_devices = "XXX" is not valid. Device "XXX" not found in "ball_devices:" section in your config. Error Code: CFE-ConfigValidator-6 (https://docs.missionpinball.org/en/0.55/logs/CFE-ConfigValidator-6.html)
